Workbook
Name \\\: recuperação [1]tubulão2011!$A$29:$J$29
Name \\\: recuperação [1]tubulão2011!$A$29:$J$29
Name \\\: recuperação [1]tubulão2011!$A$29:$J$29
Name \c: #REF!
Name \c: #REF!
Name \c: #REF!
Name \i: #REF!
Name \i: #REF!
Name \i: #REF!
Name \L: #REF!
Name \L: #REF!
Name \L: #REF!
Name \M: #REF!
Name \M: #REF!
Name \M: #REF!
Name \O: #REF!
Name \O: #REF!
Name \O: #REF!
Name \p: #REF!
Name \p: #REF!
Name \p: #REF!
Name \Q: #REF!
Name \Q: #REF!
Name \Q: #REF!
Name \R: #REF!
Name \R: #REF!
Name \R: #REF!
Name \S: #REF!
Name \S: #REF!
Name \S: #REF!
Name \T: #REF!
Name \T: #REF!
Name \T: #REF!
Name \u: #REF!
Name \u: #REF!
Name \u: #REF!
Name \X: #REF!
Name \X: #REF!
Name \X: #REF!
Name \Z: #REF!
Name \Z: #REF!
Name \Z: #REF!
Name ____Orc2000: #REF!
Name ____Orc2000: #REF!
Name ____Orc2000: #REF!
Name ___Orc2000: #REF!
Name ___Orc2000: #REF!
Name ___Orc2000: #REF!
Name __Orc2000: #REF!
Name __Orc2000: #REF!
Name __Orc2000: #REF!
Name _1_US: "Dolar Exchange"
Name _1994: #REF!
Name _1994: #REF!
Name _1994: #REF!
Name _1995: #REF!
Name _1995: #REF!
Name _1995: #REF!
Name _1996: #REF!
Name _1996: #REF!

Sheet Índice
B6: Ítem exigido pelo Termo de referência | K6: Localização
K7: Planilha | L7: Célula | M7: Link
B9: Painel de controle (sumário); | K9: Controle | L9: A1 | M9: ='LOTE 3'!$A$1 -> Controle
B10: Demonstração de Fluxo de Caixa Direto e Indireto; | K10: MF | L10: A170 | M10: =#REF! -> #REF!
B11: Cálculo dos indicadores econômicos: Valor Presente Líquido (VPL), Taxa Interna de Retorno (TIR) do Projeto, Payback, etc.; | K11: MF | L11: A40 | M11: =#REF! -> #REF!
B12: Investimentos e manutenções periódicas (CAPEX); | K12: Capex | L12: A6 | M12: =Capex!$A$6 -> CAPEX
B13: Depreciações e amortizações; | K13: MF | L13: A1446 | M13: =#REF! -> #REF!
B14: Receitas:
B15: Receitas de contraprestação | K15: Receita de CP | L15: A7 | M15: ='Receita CP'!$A$7 -> Contraprestação anual
B16: Receitas acessórias | K16: Receita Acessórias | L16: A1 | M16: ='Receita Acessórias'!$A$1 -> Receitas Acessórias
B17: Custos de operação e manutenção (OPEX); | K17: Opex | L17: A22 | M17: =Opex!$A$53 -> Opex / Por item [valores reais]
B18: Custo médio ponderado de capital (WACC); e | K18: MF | L18: A1518 | M18: =#REF! -> #REF!
B19: Análises de Sensibilidade. | K19: Controle | L19: A202 | M19: ='LOTE 3'!#REF! -> #REF!
B20: Value For Money do Projeto e Justificativa Econômica da Concessão | K20: VfM | L20: A1 | M20: =VfM!A1 -> Value for Money
B21: Análise de Impacto Orçamentário e Fiscal | K21: VfM | L21: A66 | M21: =VfM!A66 -> Projeção comprometimento RCL / Cenários cobrança taxa do lixo
B22: estrutura de taxas e tributos existentes e propostos | K22: VfM | L22: A72 | M22: =VfM!A72 -> Cenário 1: taxa de R$ 14,8 por domicílio / mês
B32: Planilha | F32: Conteúdo
B34: Controle | F34: Input de variáveis sensíveis e visão do resultado do modelo
B35: Premissas | F35: Premissas financeiras, impostos etc
B36: MF | F36: Modelo Econômico-Financeiro
B37: VfM | F37: Análise quantitativa de Value for Money
B38: Operacional | F38: Construção da geração de resíduos por município, tipo de resíduo e outros
B39: Receita de CP | F39: Cálculo da receitas de contraprestação
B40: Receitas acessórias | F40: Cálculo da receitas acessórias a serem exploradas pelo concessionário
B41: Opex | F41: Custos operacionais
B42: Opex_Input | F42: Inputs de custos operacionais dos Estudos de Infraestrutura e operação
B43: Capex | F43: Cronograma de desembolso do Capex e cálculo depreciação
B44: Capex_Input | F44: Inputs de dados de investimentos dos Estudos de Infraestrutura e operação
... B58: Transferido | F58: Célula transferida de outra planilha

Sheet LOTE 3
A1: Controle
BL3: Com inflação | BO3: Alternativa 1
A4: Modelo Real ou nominal | B4: Com inflação | D4: WACC | E4: 0.1 | BL4: Sem inflação
A5: VPL | B5: ='DRE_URE MARÍLIA-BIO+GAS'!I80 -> 95957006 | C5: MM R$ | D5: TIR projeto | E5: ='DRE_URE MARÍLIA-BIO+GAS'!I79 -> 0.11637598
D6: Payback | E6: ='DRE_URE MARÍLIA-BIO+GAS'!I81 -> 6.7 | F6: COM LPU | G6: SEM LPU
A7: Contraprestação fixa | B7: 2.8540916 | C7: MM R$/ano | F7: 2.8540916 | G7: 2.8540916
A8: Saldo final ativo financeiro | B8: =#REF! -> #REF! | F8: =#REF! -> #REF! | G8: =#REF! -> #REF!
A9: Contraprestação variável - Parcela B Volume | B9: 110 | C9: R$/ton | F9: 110 | G9: 110
A10: Contraprestação variável - Parcela C População | B10: 4.7269692 | C10: R$/hab/mês | F10: 4.7269692 | G10: 2.9928665
A12: Sensibilidade preço de recicláveis | B12: 0 | F12: 0 | G12: 0
A13: Sensibilidade crédito recicláveis | B13: 0 | F13: 0 | G13: 0
A14: Outorga variável | B14: 0 | F14: 0 | G14: 0
A15: Anos de carência de outorga variável | B15: 0 | F15: 0 | G15: 0
A16: Primeiro ano de pagamento integral | B16: 1 | F16: 1 | G16: 1
A18: Fator Capex | B18: 1 | F18: 1 | G18: 1
A19: Fator Opex | B19: 1 | F19: 1 | G19: 1
A21: Capital social mínimo 1o ano | B21: 10 | C21: MM R$ | F21: 10 | G21: 10
A23: Considera limpeza urbana? | B23: 1 | C23: [1=sim;0=não] | F23: 1 | G23: 0
A25: Alavancagem alvo | B25: 1 | F25: 1 | G25: 1
A27: Síntese
A28: Componentes de valor / Waterfall VPL
H29: =YEAR(Premissas!$D$13) -> 2025 | I29: =H29+1 -> 2026 | J29: =I29+1 -> 2027 | K29: =J29+1 -> 2028 | L29: =K29+1 -> 2029 | M29: =L29+1 -> 2030 | N29: =M29+1 -> 2031 | O29: =N29+1 -> 2032 | P29: =O29+1 -> 2033 | ... AP29: =AO29+1 -> 2059
A30: Índice de inflação brasileira (IPCA) | H30: =MacroEco!AA$8 -> 1.0714036 | I30: =MacroEco!AB$8 -> 1.1035457 | J30: =MacroEco!AC$8 -> 1.1366521 | K30: =MacroEco!AD$8 -> 1.1707517 | L30: =MacroEco!AE$8 -> 1.2058742 | M30: =MacroEco!AF$8 -> 1.2420504 | N30: =MacroEco!AG$8 -> 1.2793119 | O30: =MacroEco!AH$8 -> 1.3176913 | ... AP30: =MacroEco!BI$8 -> 2.9269732
A32: Em termos nominais
A33: Receita Bruta - URE MARÍLIA - BIO+GAS | D33: =SUM(H33:AQ33) -> 1.0075865e+09 | H33: =SUM(H34:H39) -> 4710.4288 | I33: =SUM(I34:I39) -> 19031970 | J33: =SUM(J34:J39) -> 29951356 | K33: =SUM(K34:K39) -> 29951549 | L33: =SUM(L34:L39) -> 29951750 | M33: =SUM(M34:M39) -> 29951957 | N33: =SUM(N34:N39) -> 29952173 | O33: =SUM(O34:O39) -> 29952397 | ... AP33: =SUM(AP34:AP39) -> 29962351
A34: (+) Receita Contraprestação fixa | D34: =SUM(H34:AQ34) -> 229132800 | H34: ='DRE_URE MARÍLIA-BIO+GAS'!E8 -> 0 | I34: ='DRE_URE MARÍLIA-BIO+GAS'!F8 -> 6739200 | J34: ='DRE_URE MARÍLIA-BIO+GAS'!G8 -> 6739200 | K34: ='DRE_URE MARÍLIA-BIO+GAS'!H8 -> 6739200 | L34: ='DRE_URE MARÍLIA-BIO+GAS'!I8 -> 6739200 | M34: ='DRE_URE MARÍLIA-BIO+GAS'!J8 -> 6739200 | N34: ='DRE_URE MARÍLIA-BIO+GAS'!K8 -> 6739200 | O34: ='DRE_URE MARÍLIA-BIO+GAS'!L8 -> 6739200 | ... AP34: ='DRE_URE MARÍLIA-BIO+GAS'!AM8 -> 6739200
A35: (+) Receita Reciclável | D35: =SUM(H35:AQ35) -> 332157 | H35: ='Receita Acessórias'!O18 -> 4710.4288 | I35: ='Receita Acessórias'!P18 -> 4890.2048 | J35: ='Receita Acessórias'!Q18 -> 5075.7357 | K35: ='Receita Acessórias'!R18 -> 5268.8133 | L35: ='Receita Acessórias'!S18 -> 5469.748 | M35: ='Receita Acessórias'!T18 -> 5677.1311 | N35: ='Receita Acessórias'!U18 -> 5892.9261 | O35: ='Receita Acessórias'!V18 -> 6117.478 | ... AO35: ='Receita Acessórias'!AV18 -> 16071.17 | AP35: =AO35 -> 16071.17
A36: (+) Receita Biometano | D36: =SUM(H36:AQ36) -> 257040000 | H36: ='DRE_URE MARÍLIA-BIO+GAS'!E5 -> 0 | I36: ='DRE_URE MARÍLIA-BIO+GAS'!F5 -> 7560000 | J36: ='DRE_URE MARÍLIA-BIO+GAS'!G5 -> 7560000 | K36: ='DRE_URE MARÍLIA-BIO+GAS'!H5 -> 7560000 | L36: ='DRE_URE MARÍLIA-BIO+GAS'!I5 -> 7560000 | M36: ='DRE_URE MARÍLIA-BIO+GAS'!J5 -> 7560000 | N36: ='DRE_URE MARÍLIA-BIO+GAS'!K5 -> 7560000 | O36: ='DRE_URE MARÍLIA-BIO+GAS'!L5 -> 7560000 | ... AP36: ='DRE_URE MARÍLIA-BIO+GAS'!AM5 -> 7560000
A37: (+) Receita Energia Elétrica | D37: =SUM(H37:AQ37) -> 360333600 | H37: ='DRE_URE MARÍLIA-BIO+GAS'!E6 -> 0 | I37: ='DRE_URE MARÍLIA-BIO+GAS'!F6 -> 0 | J37: ='DRE_URE MARÍLIA-BIO+GAS'!G6 -> 10919200 | K37: ='DRE_URE MARÍLIA-BIO+GAS'!H6 -> 10919200 | L37: ='DRE_URE MARÍLIA-BIO+GAS'!I6 -> 10919200 | M37: ='DRE_URE MARÍLIA-BIO+GAS'!J6 -> 10919200 | N37: ='DRE_URE MARÍLIA-BIO+GAS'!K6 -> 10919200 | O37: ='DRE_URE MARÍLIA-BIO+GAS'!L6 -> 10919200 | ... AP37: ='DRE_URE MARÍLIA-BIO+GAS'!AM6 -> 10919200
A38: (+) Receita CO2 | D38: =SUM(H38:AQ38) -> 144585000 | H38: ='DRE_URE MARÍLIA-BIO+GAS'!E7 -> 0 | I38: ='DRE_URE MARÍLIA-BIO+GAS'!F7 -> 4252500 | J38: ='DRE_URE MARÍLIA-BIO+GAS'!G7 -> 4252500 | K38: ='DRE_URE MARÍLIA-BIO+GAS'!H7 -> 4252500 | L38: ='DRE_URE MARÍLIA-BIO+GAS'!I7 -> 4252500 | M38: ='DRE_URE MARÍLIA-BIO+GAS'!J7 -> 4252500 | N38: ='DRE_URE MARÍLIA-BIO+GAS'!K7 -> 4252500 | O38: ='DRE_URE MARÍLIA-BIO+GAS'!L7 -> 4252500 | ... AP38: ='DRE_URE MARÍLIA-BIO+GAS'!AM7 -> 4252500
A39: (+) CBIOS | D39: =SUM(H39:AQ39) -> 16162920 | H39: ='DRE_URE MARÍLIA-BIO+GAS'!E10 -> 0 | I39: ='DRE_URE MARÍLIA-BIO+GAS'!F10 -> 475380 | J39: ='DRE_URE MARÍLIA-BIO+GAS'!G10 -> 475380 | K39: ='DRE_URE MARÍLIA-BIO+GAS'!H10 -> 475380 | L39: ='DRE_URE MARÍLIA-BIO+GAS'!I10 -> 475380 | M39: ='DRE_URE MARÍLIA-BIO+GAS'!J10 -> 475380 | N39: ='DRE_URE MARÍLIA-BIO+GAS'!K10 -> 475380 | O39: ='DRE_URE MARÍLIA-BIO+GAS'!L10 -> 475380 | ... AP39: ='DRE_URE MARÍLIA-BIO+GAS'!AM10 -> 475380
A40: Impostos | D40: =SUM(H40:AQ40) -> -1.8693681e+08 | H40: =SUM(H41:H42) -> 0 | I40: =SUM(I41:I42) -> -4517822.2 | J40: =SUM(J41:J42) -> -5527848.2 | K40: =SUM(K41:K42) -> -5527848.2 | L40: =SUM(L41:L42) -> -5527848.2 | M40: =SUM(M41:M42) -> -5527848.2 | N40: =SUM(N41:N42) -> -5527848.2 | O40: =SUM(O41:O42) -> -5527848.2 | ... AP40: =SUM(AP41:AP42) -> -5527848.2
A41: (-) Impostos Serviço | D41: =SUM(H41:AQ41) -> -77905152 | H41: ='DRE_URE MARÍLIA-BIO+GAS'!E41 -> 0 | I41: ='DRE_URE MARÍLIA-BIO+GAS'!F41 -> -2291328 | J41: ='DRE_URE MARÍLIA-BIO+GAS'!G41 -> -2291328 | K41: ='DRE_URE MARÍLIA-BIO+GAS'!H41 -> -2291328 | L41: ='DRE_URE MARÍLIA-BIO+GAS'!I41 -> -2291328 | M41: ='DRE_URE MARÍLIA-BIO+GAS'!J41 -> -2291328 | N41: ='DRE_URE MARÍLIA-BIO+GAS'!K41 -> -2291328 | O41: ='DRE_URE MARÍLIA-BIO+GAS'!L41 -> -2291328 | ... AP41: ='DRE_URE MARÍLIA-BIO+GAS'!AM41 -> -2291328
A42: (-) Impostos Produto | D42: =SUM(H42:AQ42) -> -1.0903166e+08 | H42: ='DRE_URE MARÍLIA-BIO+GAS'!E12 -> 0 | I42: ='DRE_URE MARÍLIA-BIO+GAS'!F12 -> -2226494.2 | J42: ='DRE_URE MARÍLIA-BIO+GAS'!G12 -> -3236520.2 | K42: ='DRE_URE MARÍLIA-BIO+GAS'!H12 -> -3236520.2 | L42: ='DRE_URE MARÍLIA-BIO+GAS'!I12 -> -3236520.2 | M42: ='DRE_URE MARÍLIA-BIO+GAS'!J12 -> -3236520.2 | N42: ='DRE_URE MARÍLIA-BIO+GAS'!K12 -> -3236520.2 | O42: ='DRE_URE MARÍLIA-BIO+GAS'!L12 -> -3236520.2 | ... AP42: ='DRE_URE MARÍLIA-BIO+GAS'!AM12 -> -3236520.2
A43: OPEX | D43: =SUM(H43:AQ43) -> -1.7836593e+08 | H43: =SUM(H44:H44) -> -954720 | I43: =SUM(I44:I44) -> -5059006.2 | J43: =SUM(J44:J44) -> -5222794.2 | K43: =SUM(K44:K44) -> -5222794.2 | L43: =SUM(L44:L44) -> -5222794.2 | M43: =SUM(M44:M44) -> -5222794.2 | N43: =SUM(N44:N44) -> -5222794.2 | O43: =SUM(O44:O44) -> -5222794.2 | ... AP43: =SUM(AP44:AP44) -> -5222794.2
A44: (-) Custos com operacionais | D44: =SUM(I44:AQ44) -> -1.7741121e+08 | H44: =Opex!Z57*-1 -> -954720 | I44: =Opex!AA57*-1 -> -5059006.2 | J44: =Opex!AB57*-1 -> -5222794.2 | K44: =Opex!AC57*-1 -> -5222794.2 | L44: =Opex!AD57*-1 -> -5222794.2 | M44: =Opex!AE57*-1 -> -5222794.2 | N44: =Opex!AF57*-1 -> -5222794.2 | O44: =Opex!AG57*-1 -> -5222794.2 | ... AO44: =Opex!BG57*-1 -> -5222794.2 | AP44: =AO44 -> -5222794.2
A45: Custos de construção | D45: =SUM(H45:AQ45) -> -40600000 | H45: =H46 -> 0 | I45: =I46 -> -4060000 | J45: =J46 -> -4060000 | K45: =K46 -> -4060000 | L45: =L46 -> -4060000 | M45: =M46 -> -4060000 | N45: =N46 -> -4060000 | O45: =O46 -> -4060000 | ... AP45: =AP46 -> 0
A46: (-) Depreciação/Amortização | D46: =SUM(H46:AQ46) -> -40600000 | H46: ='DRE_URE MARÍLIA-BIO+GAS'!E36 -> 0 | I46: ='DRE_URE MARÍLIA-BIO+GAS'!F36 -> -4060000 | J46: ='DRE_URE MARÍLIA-BIO+GAS'!G36 -> -4060000 | K46: ='DRE_URE MARÍLIA-BIO+GAS'!H36 -> -4060000 | L46: ='DRE_URE MARÍLIA-BIO+GAS'!I36 -> -4060000 | M46: ='DRE_URE MARÍLIA-BIO+GAS'!J36 -> -4060000 | N46: ='DRE_URE MARÍLIA-BIO+GAS'!K36 -> -4060000 | O46: ='DRE_URE MARÍLIA-BIO+GAS'!L36 -> -4060000 | ... AP46: ='DRE_URE MARÍLIA-BIO+GAS'!AM36 -> 0
A47: (=) EBIT | D47: =SUM(H47:AQ47) -> 7.8004966e+08 | H47: =SUM(H48:H50) -> 4710.4288 | I47: =SUM(I48:I50) -> 10454148 | J47: =SUM(J48:J50) -> 20363507 | K47: =SUM(K48:K50) -> 20363701 | L47: =SUM(L48:L50) -> 20363901 | M47: =SUM(M48:M50) -> 20364109 | N47: =SUM(N48:N50) -> 20364325 | O47: =SUM(O48:O50) -> 20364549 | ... AP47: =SUM(AP48:AP50) -> 24434503
A48: (-) Impostos sobre EBIT | D48: =SUM(H48:AQ48) -> -1.8693681e+08 | H48: =H40 -> 0 | I48: =I40 -> -4517822.2 | J48: =J40 -> -5527848.2 | K48: =K40 -> -5527848.2 | L48: =L40 -> -5527848.2 | M48: =M40 -> -5527848.2 | N48: =N40 -> -5527848.2 | O48: =O40 -> -5527848.2 | ... AP48: =AP40 -> -5527848.2
...

Sheet Premissas
A1: Premissas | B1: Unidade | D1: VALOR ATIVO | E1: Unidade | F1: Fonte
A2: PARÂMETROS DE VALORAÇÃO
A3: Primeiro ano de projeção do modelo financeiro | D3: 2026 | E3: [ano] | F3: Alterar no início e manter fixo posteriormente (para manter inputs consistentes com anos)
A4: Ano base de inflação | D4: 2026 | E4: [ano]
A5: Data de valoração (31/12/....) | D5: 2026 | E5: [data]
A6: Taxa de desconto para projeto | B6: % a.a. real | D6: =#REF! -> #REF! | E6: % a.a. real
A7: Taxa de desconto para acionista | B7: % a.a. real | D7: =#REF! -> #REF! | E7: % a.a. real
A8: Modelo calculado em termos nominais ou reais? | D8: =MATCH('LOTE 3'!$B$4,'LOTE 3'!BL3:BL4,0) -> 1 | E8: [1: Nominais; 2: Reais]
A9: Considera receita financeira? | D9: 1 | E9: [1: Sim; 2: Não]
A11: PARÂMETROS DE CONTRATO
A12: TIMING
A13: Data de início de projeto | D13: 45658 | E13: [data]
A14: Anos de projeto | D14: 35 | E14: anos
A15: Término de projeto | D15: =EDATE(D13,12*D14) -> 58441 | E15: [data]
A16: 1o ano de projeto | D16: =YEAR(D13) -> 2025 | E16: [ano]
A17: 1o ano de operação | D17: 2027 | E17: [ano] | F17: [Utilizado para fins de início de depreciação e ativação de juros capitalizados]
A18: Último ano do projeto | D18: =YEAR(D15)-1 -> 2059 | E18: [ano]
A20: CAPEX GARANTIDO (reinvestimentos) | B20: ='LOTE 3'!$B$7 -> 2.8540916
A21: =Capex!A8 -> URE MARÍLIA - BIO+GÁS | B21: flag
A22: =Capex!A9 -> Custos pré-operacionais | B22: =IF($B$20>0,"G","NG") -> G | C22: [G: garantido; NG: não garantido]
A23: =Capex!A10 -> Licenciamento (estudos, projetos e licenças) | B23: NG | C23: [G: garantido; NG: não garantido]
A24: =Capex!A13 -> URE MARÍLIA - BIO
A25: =Capex!A14 -> Custos pré-operacionais | B25: =IF($B$20>0,"G","NG") -> G | C25: [G: garantido; NG: não garantido]
A26: =Capex!A15 -> Licenciamento (estudos, projetos e licenças) | B26: NG | C26: [G: garantido; NG: não garantido]
A27: =Capex!A18 -> URE MARÍLIA - GÁS
A28: =Capex!A19 -> Custos pré-operacionais | B28: =IF($B$20>0,"G","NG") -> G | C28: [G: garantido; NG: não garantido]
A29: =Capex!A20 -> Licenciamento (estudos, projetos e licenças) | B29: NG | C29: [G: garantido; NG: não garantido]
A31: FINANCIAMENTO | D31: =#REF! -> #REF! | E31: =#REF! -> #REF! | F31: =#REF! -> #REF! | G31: =#REF! -> #REF! | H31: =#REF! -> #REF! | I31: =#REF! -> #REF! | J31: =#REF! -> #REF! | K31: =#REF! -> #REF! | L31: =#REF! -> #REF!
D32: 1 | E32: 2 | F32: 3 | G32: 4 | H32: 5 | I32: 6 | J32: 7 | K32: 8 | L32: CAIXA
A33: Linha de financiamento | D33: FINEM | E33: FINEM | F33: FINEM | G33: FINEM | H33: FINEM | I33: FINEM | J33: FINEM | K33: FINEM
A34: Primeiro pagamento amortização | B34: data | D34: =#REF! -> #REF! | E34: =#REF! -> #REF! | F34: =#REF! -> #REF! | G34: =#REF! -> #REF! | H34: =#REF! -> #REF! | I34: =#REF! -> #REF! | J34: =#REF! -> #REF! | K34: =#REF! -> #REF! | L34: =#REF! -> #REF!
A35: Último pagamento amortização | B35: data | D35: =D34+D38 -> #REF! | E35: =E34+E38 -> #REF! | F35: =F34+F38 -> #REF! | G35: =G34+G38 -> #REF! | H35: =H34+H38 -> #REF! | I35: =I34+I38 -> #REF! | J35: =J34+J38 -> #REF! | K35: =K34+K38 -> #REF! | L35: =L34+L38 -> #REF!
A36: Início de captação | B36: data | D36: 2024 | E36: 2029 | F36: 2034 | G36: 2039 | H36: 2044 | I36: 2046 | J36: 2049 | K36: 2054
A37: Duração de captação | B37: anos | D37: 3 | E37: 1 | F37: 3 | G37: 1 | H37: 2 | I37: 1 | J37: 1 | K37: 2
A38: Prazo da amortização | B38: anos | D38: 31 | E38: 5 | F38: 5 | G38: 5 | H38: 5 | I38: 5 | J38: 5 | K38: 3 | L38: 20
A39: Prazo da carência | B39: anos | D39: 3 | E39: 1 | F39: 1 | G39: 1 | H39: 1 | I39: 1 | J39: 1 | K39: 1 | L39: 4
A40: Anos entre captação e primeiro pagamento de juros | B40: anos | D40: =D39 -> 3 | E40: =E39 -> 1 | F40: =F39 -> 1 | G40: =G39 -> 1 | H40: =H39 -> 1 | I40: =I39 -> 1 | J40: =J39 -> 1 | K40: =K39 -> 1 | L40: =L39 -> 4
A41: Alavancagem | B41: % | D41: 0 | E41: 0 | F41: 0 | G41: 0 | H41: 0 | I41: 0 | J41: 0 | K41: 0 | L41: 0
A43: Empréstimo Ponte
A44: Spread empréstimo ponte | D44: 0.03 | E44: % a.a.
...

Sheet Apoio
F2: Projeção Macroeconômica – Brasil (% a.a.) | Q2: Projeção Anual de Demanda de RSD – Marília/SP (2025–2059)
F4: Horizonte: 35 anos
F6: Ano | G6: IPCA (%) | H6: Selic (%) | I6: PIB (%) | K6: Ano | M6: Selic | N6: IPCA | O6: PIB | Q6: Ano | R6: População estimada | S6: Geração de RSD (t/dia) | T6: Geração de RSD (t/ano) | V6: Ano | X6: População | Y6: RSU | Z6: RSU
F7: 2025 | G7: 4.8 | H7: 15 | I7: 2.2 | M7: % a.a. | N7: % a.a. | O7: % a.a. | Q7: 2025 | R7: 248526 | S7: 201.5 | T7: 63070 | Y7: t/dia | Z7: t/ano
F8: 2026 | G8: 4.3 | H8: 12.3 | I8: 1.8 | K8: 1 | L8: 2026 | M8: 15 | N8: 4.8 | O8: 2.2 | Q8: 2026 | R8: 250440 | S8: 203.1 | T8: 63570 | V8: 1 | W8: 2026 | X8: 248526 | Y8: 201.5 | Z8: 63070
F9: 2027 | G9: 3.9 | H9: 10.5 | I9: 1.8 | K9: 2 | L9: 2027 | M9: 12.3 | N9: 4.3 | O9: 1.8 | Q9: 2027 | R9: 252369 | S9: 204.6 | T9: 64060 | V9: 2 | W9: 2027 | X9: 250440 | Y9: 203.1 | Z9: 63570
F10: 2028 | G10: 3.7 | H10: 9.5 | I10: 2 | K10: 3 | L10: 2028 | M10: 10.5 | N10: 3.9 | O10: 1.8 | Q10: 2028 | R10: 254313 | S10: 206.2 | T10: 64560 | V10: 3 | W10: 2028 | X10: 252369 | Y10: 204.6 | Z10: 64060
F11: 2029 | G11: 3.6 | H11: 9 | I11: 2.1 | K11: 4 | L11: 2029 | M11: 9.5 | N11: 3.7 | O11: 2 | Q11: 2029 | R11: 256230 | S11: 207.8 | T11: 65070 | V11: 4 | W11: 2029 | X11: 254313 | Y11: 206.2 | Z11: 64560
F12: 2030 | G12: 3.5 | H12: 8.8 | I12: 2.2 | K12: 5 | L12: 2030 | M12: 9 | N12: 3.6 | O12: 2.1 | Q12: 2030 | R12: 258242 | S12: 209.4 | T12: 65570 | V12: 5 | W12: 2030 | X12: 256230 | Y12: 207.8 | Z12: 65070
F13: 2031 | G13: 3.4 | H13: 8.6 | I13: 2.3 | K13: 6 | L13: 2031 | M13: 8.8 | N13: 3.5 | O13: 2.2 | Q13: 2031 | R13: 260277 | S13: 211.1 | T13: 66080 | V13: 6 | W13: 2031 | X13: 258242 | Y13: 209.4 | Z13: 65570
F14: 2032 | G14: 3.3 | H14: 8.4 | I14: 2.4 | K14: 7 | L14: 2032 | M14: 8.6 | N14: 3.4 | O14: 2.3 | Q14: 2032 | R14: 262335 | S14: 212.8 | T14: 66600 | V14: 7 | W14: 2032 | X14: 260277 | Y14: 211.1 | Z14: 66080
F15: 2033 | G15: 3.2 | H15: 8.2 | I15: 2.5 | K15: 8 | L15: 2033 | M15: 8.4 | N15: 3.3 | O15: 2.4 | Q15: 2033 | R15: 264416 | S15: 214.5 | T15: 67120 | V15: 8 | W15: 2033 | X15: 262335 | Y15: 212.8 | Z15: 66600
F16: 2034 | G16: 3.1 | H16: 8 | I16: 2.5 | K16: 9 | L16: 2034 | M16: 8.2 | N16: 3.2 | O16: 2.5 | Q16: 2034 | R16: 266189 | S16: 215.9 | T16: 67590 | V16: 9 | W16: 2034 | X16: 264416 | Y16: 214.5 | Z16: 67120
F17: 2035 | G17: 3 | H17: 7.8 | I17: 2.6 | K17: 10 | L17: 2035 | M17: 8 | N17: 3.1 | O17: 2.5 | Q17: 2035 | R17: 268315 | S17: 217.7 | T17: 68140 | V17: 10 | W17: 2035 | X17: 266189 | Y17: 215.9 | Z17: 67590
F18: 2036 | G18: 3 | H18: 7.6 | I18: 2.6 | K18: 11 | L18: 2036 | M18: 7.8 | N18: 3 | O18: 2.6 | Q18: 2036 | R18: 270463 | S18: 219.4 | T18: 68690 | V18: 11 | W18: 2036 | X18: 268315 | Y18: 217.7 | Z18: 68140
F19: 2037 | G19: 3 | H19: 7.5 | I19: 2.6 | K19: 12 | L19: 2037 | M19: 7.6 | N19: 3 | O19: 2.6 | Q19: 2037 | R19: 272633 | S19: 221.2 | T19: 69250 | V19: 12 | W19: 2037 | X19: 270463 | Y19: 219.4 | Z19: 68690
... F41: 2059 | G41: 3 | H41: 6.5 | I41: 2.6 | K41: 34 | L41: 2059 | M41: 6.5 | N41: 3 | O41: 2.6 | Q41: 2059 | R41: 321923 | S41: 261.1 | T41: 81730 | V41: 34 | W41: 2059 | X41: 319686 | Y41: 259.2 | Z41: 81130
K42: 35 | L42: 2060 | M42: 6.5 | N42: 3 | O42: 2.6 | V42: 35 | W42: 2060 | X42: 321923 | Y42: 261.1 | Z42: 81730
H47: 0.45 | I47: 0.34 | J47: 0.05 | K47: 0.16
F48: Ano | G48: Geração de RSD (t/ano) | H48: úmida | I48: seca | J48: metais /vidros | K48: Rejeitos | M48: Materiais segregados
F49: 2025 | G49: 63070 | H49: =$H47*G49 -> 28381.5 | I49: =G49*$I$47 -> 21443.8 | J49: =G49*$J$47 -> 3153.5 | K49: =G49*$K$47 -> 10091.2 | M49: Ano | O49: RSU | P49: Metais Vidros | Q49: Fração Úmida | R49: Fração Seca | S49: Rejeitos
F50: 2026 | G50: 63570 | H50: =$H$47*G50 -> 28606.5 | I50: =G50*$I$47 -> 21613.8 | J50: =G50*$J$47 -> 3178.5 | K50: =G50*$K$47 -> 10171.2 | O50: t/ano | P50: t/ano | Q50: t/ano | R50: t/ano | S50: t/ano
F51: 2027 | G51: 64060 | H51: =$H$47*G51 -> 28827 | I51: =G51*$I$47 -> 21780.4 | J51: =G51*$J$47 -> 3203 | K51: =G51*$K$47 -> 10249.6 | M51: 1 | N51: 2026 | O51: 63070 | P51: 3153.5 | Q51: 28381.5 | R51: 21443.8 | S51: 10091.2
F52: 2028 | G52: 64560 | H52: =$H$47*G52 -> 29052 | I52: =G52*$I$47 -> 21950.4 | J52: =G52*$J$47 -> 3228 | K52: =G52*$K$47 -> 10329.6 | M52: 2 | N52: 2027 | O52: 63570 | P52: 3178.5 | Q52: 28606.5 | R52: 21613.8 | S52: 10171.2
F53: 2029 | G53: 65070 | H53: =$H$47*G53 -> 29281.5 | I53: =G53*$I$47 -> 22123.8 | J53: =G53*$J$47 -> 3253.5 | K53: =G53*$K$47 -> 10411.2 | M53: 3 | N53: 2028 | O53: 64060 | P53: 3203 | Q53: 28827 | R53: 21780.4 | S53: 10249.6
F54: 2030 | G54: 65570 | H54: =$H$47*G54 -> 29506.5 | I54: =G54*$I$47 -> 22293.8 | J54: =G54*$J$47 -> 3278.5 | K54: =G54*$K$47 -> 10491.2 | M54: 4 | N54: 2029 | O54: 64560 | P54: 3228 | Q54: 29052 | R54: 21950.4 | S54: 10329.6
F55: 2031 | G55: 66080 | H55: =$H$47*G55 -> 29736 | I55: =G55*$I$47 -> 22467.2 | J55: =G55*$J$47 -> 3304 | K55: =G55*$K$47 -> 10572.8 | M55: 5 | N55: 2030 | O55: 65070 | P55: 3253.5 | Q55: 29281.5 | R55: 22123.8 | S55: 10411.2
F56: 2032 | G56: 66600 | H56: =$H$47*G56 -> 29970 | I56: =G56*$I$47 -> 22644 | J56: =G56*$J$47 -> 3330 | K56: =G56*$K$47 -> 10656 | M56: 6 | N56: 2031 | O56: 65570 | P56: 3278.5 | Q56: 29506.5 | R56: 22293.8 | S56: 10491.2
F57: 2033 | G57: 67120 | H57: =$H$47*G57 -> 30204 | I57: =G57*$I$47 -> 22820.8 | J57: =G57*$J$47 -> 3356 | K57: =G57*$K$47 -> 10739.2 | M57: 7 | N57: 2032 | O57: 66080 | P57: 3304 | Q57: 29736 | R57: 22467.2 | S57: 10572.8
F58: 2034 | G58: 67590 | H58: =$H$47*G58 -> 30415.5 | I58: =G58*$I$47 -> 22980.6 | J58: =G58*$J$47 -> 3379.5 | K58: =G58*$K$47 -> 10814.4 | M58: 8 | N58: 2033 | O58: 66600 | P58: 3330 | Q58: 29970 | R58: 22644 | S58: 10656
F59: 2035 | G59: 68140 | H59: =$H$47*G59 -> 30663 | I59: =G59*$I$47 -> 23167.6 | J59: =G59*$J$47 -> 3407 | K59: =G59*$K$47 -> 10902.4 | M59: 9 | N59: 2034 | O59: 67120 | P59: 3356 | Q59: 30204 | R59: 22820.8 | S59: 10739.2
F60: 2036 | G60: 68690 | H60: =$H$47*G60 -> 30910.5 | I60: =G60*$I$47 -> 23354.6 | J60: =G60*$J$47 -> 3434.5 | K60: =G60*$K$47 -> 10990.4 | M60: 10 | N60: 2035 | O60: 67590 | P60: 3379.5 | Q60: 30415.5 | R60: 22980.6 | S60: 10814.4
F61: 2037 | G61: 69250 | H61: =$H$47*G61 -> 31162.5 | I61: =G61*$I$47 -> 23545 | J61: =G61*$J$47 -> 3462.5 | K61: =G61*$K$47 -> 11080 | M61: 11 | N61: 2036 | O61: 68140 | P61: 3407 | Q61: 30663 | R61: 23167.6 | S61: 10902.4
F62: 2038 | G62: 69800 | H62: =$H$47*G62 -> 31410 | I62: =G62*$I$47 -> 23732 | J62: =G62*$J$47 -> 3490 | K62: =G62*$K$47 -> 11168 | M62: 12 | N62: 2037 | O62: 68690 | P62: 3434.5 | Q62: 30910.5 | R62: 23354.6 | S62: 10990.4
... F83: 2059 | G83: 81730 | H83: =$H$47*G83 -> 36778.5 | I83: =G83*$I$47 -> 27788.2 | J83: =G83*$J$47 -> 4086.5 | K83: =G83*$K$47 -> 13076.8 | M83: 33 | N83: 2058 | O83: 80500 | P83: 4025 | Q83: 36225 | R83: 27370 | S83: 12880
M84: 34 | N84: 2059 | O84: 81130 | P84: 4056.5 | Q84: 36508.5 | R84: 27584.2 | S84: 12980.8
M85: 35 | N85: 2060 | O85: 81730 | P85: 4086.5 | Q85: 36778.5 | R85: 27788.2 | S85: 13076.8

Sheet VfM
A1: Value for Money | K1: =L1-1 -> 2021 | L1: =M1-1 -> 2022 | M1: =N1-1 -> 2023 | N1: =O1-1 -> 2024 | O1: =YEAR(Premissas!$D$13) -> 2025 | P1: =O1+1 -> 2026 | Q1: =P1+1 -> 2027 | R1: =Q1+1 -> 2028 | S1: =R1+1 -> 2029 | T1: =S1+1 -> 2030 | U1: =T1+1 -> 2031 | V1: =U1+1 -> 2032 | W1: =V1+1 -> 2033 | ... BA1: =AZ1+1 -> 2063
A2: Índice de inflação brasileira (IPCA) | L2: =MacroEco!X8 -> 0.93249867 | M2: =MacroEco!Y8 -> 0.98644232 | N2: =MacroEco!Z8 -> 1.0351726 | O2: =MacroEco!AA8 -> 1.0714036 | P2: =MacroEco!AB8 -> 1.1035457 | Q2: =MacroEco!AC8 -> 1.1366521 | R2: =MacroEco!AD8 -> 1.1707517 | S2: =MacroEco!AE8 -> 1.2058742 | ... BA2: =MacroEco!BM8 -> 0
A4: Concessão | D4: =Premissas!D6 -> #REF! | E4: a.a. real
A5: Remuneração do Poder Concedente | B5: MM R$ | D5: {=SUMPRODUCT(O5:AW5,(1/$O$2:$AW$2),$O$15:$AW$15)} -> #REF! | E5: MM R$@2021 | O5: 0 | P5: 0 | Q5: 0 | R5: 0 | S5: 0 | T5: 0 | U5: 0 | V5: 0 | W5: 0 | X5: 0 | Y5: 0 | Z5: 0 | AA5: 0 | AB5: 0 | AC5: 0 | AD5: 0 | AE5: 0 | AF5: 0 | AG5: 0 | AH5: 0 | AI5: 0 | AJ5: 0 | AK5: 0 | AL5: 0 | AM5: 0 | AN5: 0 | AO5: 0 | AP5: 0 | AQ5: 0 | AR5: 0 | AS5: 0 | AT5: 0 | AU5: 0 | AV5: 0 | AW5: 0 | AX5: 0 | AY5: 0 | AZ5: 0 | BA5: 0
A6: Fiscalização da Agência Reguladora | B6: MM R$ | D6: {=SUMPRODUCT(O6:AW6,(1/$O$2:$AW$2),$O$15:$AW$15)} -> #REF! | E6: MM R$@2021 | O6: 0 | P6: 0 | Q6: 0 | R6: 0 | S6: 0 | T6: 0 | U6: 0 | V6: 0 | W6: 0 | X6: 0 | Y6: 0 | Z6: 0 | AA6: 0 | AB6: 0 | AC6: 0 | AD6: 0 | AE6: 0 | AF6: 0 | AG6: 0 | AH6: 0 | AI6: 0 | AJ6: 0 | AK6: 0 | AL6: 0 | AM6: 0 | AN6: 0 | AO6: 0 | AP6: 0 | AQ6: 0 | AR6: 0 | AS6: 0 | AT6: 0 | AU6: 0 | AV6: 0 | AW6: 0 | AX6: 0 | AY6: 0 | AZ6: 0 | BA6: 0
A7: Custos e despesas | B7: MM R$ | D7: {=SUMPRODUCT(O7:AW7,(1/$O$2:$AW$2),$O$15:$AW$15)} -> #REF! | E7: MM R$@2021 | O7: 0 | P7: 0 | Q7: 0 | R7: 0 | S7: 0 | T7: 0 | U7: 0 | V7: 0 | W7: 0 | X7: 0 | Y7: 0 | Z7: 0 | AA7: 0 | AB7: 0 | AC7: 0 | AD7: 0 | AE7: 0 | AF7: 0 | AG7: 0 | AH7: 0 | AI7: 0 | AJ7: 0 | AK7: 0 | AL7: 0 | AM7: 0 | AN7: 0 | AO7: 0 | AP7: 0 | AQ7: 0 | AR7: 0 | AS7: 0 | AT7: 0 | AU7: 0 | AV7: 0 | AW7: 0 | AX7: 0 | AY7: 0 | AZ7: 0 | BA7: 0
A8: Contraprestação | B8: MM R$ | D8: {=SUMPRODUCT(O8:AW8,(1/$O$2:$AW$2),$O$15:$AW$15)} -> #REF! | E8: MM R$@2021 | O8: =-SUM(#REF!,#REF!) -> #REF! | P8: =-SUM(#REF!,#REF!) -> #REF! | Q8: =-SUM(#REF!,#REF!) -> #REF! | R8: =-SUM(#REF!,#REF!) -> #REF! | S8: =-SUM(#REF!,#REF!) -> #REF! | T8: =-SUM(#REF!,#REF!) -> #REF! | U8: =-SUM(#REF!,#REF!) -> #REF! | V8: =-SUM(#REF!,#REF!) -> #REF! | ... BA8: =-SUM(#REF!,#REF!) -> #REF!
A9: Investimentos | B9: MM R$ | D9: {=SUMPRODUCT(O9:AW9,(1/$O$2:$AW$2),$O$15:$AW$15)} -> #REF! | E9: MM R$@2021 | O9: 0 | P9: 0 | Q9: 0 | R9: 0 | S9: 0 | T9: 0 | U9: 0 | V9: 0 | W9: 0 | X9: 0 | Y9: 0 | Z9: 0 | AA9: 0 | AB9: 0 | AC9: 0 | AD9: 0 | AE9: 0 | AF9: 0 | AG9: 0 | AH9: 0 | AI9: 0 | AJ9: 0 | AK9: 0 | AL9: 0 | AM9: 0 | AN9: 0 | AO9: 0 | AP9: 0 | AQ9: 0 | AR9: 0 | AS9: 0 | AT9: 0 | AU9: 0 | AV9: 0 | AW9: 0 | AX9: 0 | AY9: 0 | AZ9: 0 | BA9: 0
A10: Sobrecustos operacionais | B10: MM R$ | D10: {=SUMPRODUCT(O10:AW10,(1/$O$2:$AW$2),$O$15:$AW$15)} -> #REF! | E10: MM R$@2021 | G10: 0 | H10: Sobrecusto/Desconto opção PSC | O10: =O7*$G10 -> 0 | P10: =P7*$G10 -> 0 | Q10: =Q7*$G10 -> 0 | R10: =R7*$G10 -> 0 | S10: =S7*$G10 -> 0 | T10: =T7*$G10 -> 0 | U10: =U7*$G10 -> 0 | V10: =V7*$G10 -> 0 | ... BA10: =BA7*$G10 -> 0
A11: Sobrecustos de obras | B11: MM R$ | D11: {=SUMPRODUCT(O11:AW11,(1/$O$2:$AW$2),$O$15:$AW$15)} -> #REF! | E11: MM R$@2021 | G11: 0 | H11: Sobrecusto/Desconto opção PSC | O11: =O9*$G11 -> 0 | P11: =P9*$G11 -> 0 | Q11: =Q9*$G11 -> 0 | R11: =R9*$G11 -> 0 | S11: =S9*$G11 -> 0 | T11: =T9*$G11 -> 0 | U11: =U9*$G11 -> 0 | V11: =V9*$G11 -> 0 | ... BA11: =BA9*$G11 -> 0
A12: Custos com licitação de obras | B12: MM R$ | D12: {=SUMPRODUCT(O12:AW12,(1/$O$2:$AW$2),$O$15:$AW$15)} -> #REF! | E12: MM R$@2021 | O12: 0 | P12: 0 | Q12: 0 | R12: 0 | S12: 0 | T12: 0 | U12: 0 | V12: 0 | W12: 0 | X12: 0 | Y12: 0 | Z12: 0 | AA12: 0 | AB12: 0 | AC12: 0 | AD12: 0 | AE12: 0 | AF12: 0 | AG12: 0 | AH12: 0 | AI12: 0 | AJ12: 0 | AK12: 0 | AL12: 0 | AM12: 0 | AN12: 0 | AO12: 0 | AP12: 0 | AQ12: 0 | AR12: 0 | AS12: 0 | AT12: 0 | AU12: 0 | AV12: 0 | AW12: 0 | AX12: 0 | AY12: 0 | AZ12: 0 | BA12: 0
A13: Impostos | B13: MM R$ | D13: {=SUMPRODUCT(O13:AW13,(1/$O$2:$AW$2),$O$15:$AW$15)} -> #REF! | E13: MM R$@2021 | O13: =-#REF!-#REF! -> #REF! | P13: =-#REF!-#REF! -> #REF! | Q13: =-#REF!-#REF! -> #REF! | R13: =-#REF!-#REF! -> #REF! | S13: =-#REF!-#REF! -> #REF! | T13: =-#REF!-#REF! -> #REF! | U13: =-#REF!-#REF! -> #REF! | V13: =-#REF!-#REF! -> #REF! | ... BA13: =-#REF!-#REF! -> #REF!
D14: =SUM(D5:D13) -> #REF!
A15: Fator de desconto | O15: =#REF! -> #REF! | P15: =#REF! -> #REF! | Q15: =#REF! -> #REF! | R15: =#REF! -> #REF! | S15: =#REF! -> #REF! | T15: =#REF! -> #REF! | U15: =#REF! -> #REF! | V15: =#REF! -> #REF! | ... BA15: =#REF! -> #REF!
A17: PSC | D17: 0.0617 | E17: a.a. real | F17: TESOURO IPCA+ 2035 com vencimento 15/05/2035 (https://www.tesourodireto.com.br/titulos/precos-e-taxas.htm) | G17: Acesso em: | H17: 45013
A18: Remuneração do Poder Concedente | B18: MM R$ | D18: {=SUMPRODUCT(O18:AW18,(1/$O$2:$AW$2),$O$28:$AW$28)} -> #REF! | E18: MM R$@2021 | O18: =SUM(#REF!) -> #REF! | P18: =SUM(#REF!) -> #REF! | Q18: =SUM(#REF!) -> #REF! | R18: =SUM(#REF!) -> #REF! | S18: =SUM(#REF!) -> #REF! | T18: =SUM(#REF!) -> #REF! | U18: =SUM(#REF!) -> #REF! | V18: =SUM(#REF!) -> #REF! | ... BA18: =SUM(#REF!) -> #REF!
A19: Fiscalização da Agência Reguladora | B19: MM R$ | D19: {=SUMPRODUCT(O19:AW19,(1/$O$2:$AW$2),$O$28:$AW$28)} -> #REF! | E19: MM R$@2021 | O19: 0 | P19: 0 | Q19: 0 | R19: 0 | S19: 0 | T19: 0 | U19: 0 | V19: 0 | W19: 0 | X19: 0 | Y19: 0 | Z19: 0 | AA19: 0 | AB19: 0 | AC19: 0 | AD19: 0 | AE19: 0 | AF19: 0 | AG19: 0 | AH19: 0 | AI19: 0 | AJ19: 0 | AK19: 0 | AL19: 0 | AM19: 0 | AN19: 0 | AO19: 0 | AP19: 0 | AQ19: 0 | AR19: 0 | AS19: 0 | AT19: 0 | AU19: 0 | AV19: 0 | AW19: 0 | AX19: 0 | AY19: 0 | AZ19: 0 | BA19: 0
A20: Custos e despesas | B20: MM R$ | D20: {=SUMPRODUCT(O20:AW20,(1/$O$2:$AW$2),$O$28:$AW$28)} -> #REF! | E20: MM R$@2021 | O20: =#REF! -> #REF! | P20: =#REF! -> #REF! | Q20: =#REF! -> #REF! | R20: =#REF! -> #REF! | S20: =#REF! -> #REF! | T20: =#REF! -> #REF! | U20: =#REF! -> #REF! | V20: =#REF! -> #REF! | ... BA20: =#REF! -> #REF!
A21: Contraprestação | B21: MM R$ | D21: {=SUMPRODUCT(O21:AW21,(1/$O$2:$AW$2),$O$28:$AW$28)} -> #REF! | E21: MM R$@2021 | O21: 0 | P21: 0 | Q21: 0 | R21: 0 | S21: 0 | T21: 0 | U21: 0 | V21: 0 | W21: 0 | X21: 0 | Y21: 0 | Z21: 0 | AA21: 0 | AB21: 0 | AC21: 0 | AD21: 0 | AE21: 0 | AF21: 0 | AG21: 0 | AH21: 0 | AI21: 0 | AJ21: 0 | AK21: 0 | AL21: 0 | AM21: 0 | AN21: 0 | AO21: 0 | AP21: 0 | AQ21: 0 | AR21: 0 | AS21: 0 | AT21: 0 | AU21: 0 | AV21: 0 | AW21: 0 | AX21: 0 | AY21: 0 | AZ21: 0 | BA21: 0
A22: Investimentos | B22: MM R$ | D22: {=SUMPRODUCT(O22:AW22,(1/$O$2:$AW$2),$O$28:$AW$28)} -> #REF! | E22: MM R$@2021 | O22: =#REF! -> #REF! | P22: =#REF! -> #REF! | Q22: =#REF! -> #REF! | R22: =#REF! -> #REF! | S22: =#REF! -> #REF! | T22: =#REF! -> #REF! | U22: =#REF! -> #REF! | V22: =#REF! -> #REF! | ... BA22: =#REF! -> #REF!
A23: Sobrecustos operacionais | B23: MM R$ | D23: {=SUMPRODUCT(O23:AW23,(1/$O$2:$AW$2),$O$28:$AW$28)} -> #REF! | E23: MM R$@2021 | G23: 0.2 | H23: Sobrecusto/Desconto opção PSC | O23: =O20*$G23 -> #REF! | P23: =P20*$G23 -> #REF! | Q23: =Q20*$G23 -> #REF! | R23: =R20*$G23 -> #REF! | S23: =S20*$G23 -> #REF! | T23: =T20*$G23 -> #REF! | U23: =U20*$G23 -> #REF! | V23: =V20*$G23 -> #REF! | ... BA23: =BA20*$G23 -> #REF!
A24: Sobrecustos de obras | B24: MM R$ | D24: {=SUMPRODUCT(O24:AW24,(1/$O$2:$AW$2),$O$28:$AW$28)} -> #REF! | E24: MM R$@2021 | G24: 0.2 | H24: Sobrecusto/Desconto opção PSC | O24: =O22*$G24 -> #REF! | P24: =P22*$G24 -> #REF! | Q24: =Q22*$G24 -> #REF! | R24: =R22*$G24 -> #REF! | S24: =S22*$G24 -> #REF! | T24: =T22*$G24 -> #REF! | U24: =U22*$G24 -> #REF! | V24: =V22*$G24 -> #REF! | ... BA24: =BA22*$G24 -> #REF!
A25: Custos com licitação de obras | B25: MM R$ | D25: {=SUMPRODUCT(O25:AW25,(1/$O$2:$AW$2),$O$28:$AW$28)} -> #REF! | E25: MM R$@2021 | G25: 0.0419 | O25: =$G25*(O22+O24) -> #REF! | P25: =$G25*(P22+P24) -> #REF! | Q25: =$G25*(Q22+Q24) -> #REF! | R25: =$G25*(R22+R24) -> #REF! | S25: =$G25*(S22+S24) -> #REF! | T25: =$G25*(T22+T24) -> #REF! | U25: =$G25*(U22+U24) -> #REF! | V25: =$G25*(V22+V24) -> #REF! | ... BA25: =$G25*(BA22+BA24) -> #REF!
A26: Impostos | B26: MM R$ | D26: {=SUMPRODUCT(O26:AW26,(1/$O$2:$AW$2),$O$28:$AW$28)} -> #REF! | E26: MM R$@2021 | O26: 0 | P26: 0 | Q26: 0 | R26: 0 | S26: 0 | T26: 0 | U26: 0 | V26: 0 | W26: 0 | X26: 0 | Y26: 0 | Z26: 0 | AA26: 0 | AB26: 0 | AC26: 0 | AD26: 0 | AE26: 0 | AF26: 0 | AG26: 0 | AH26: 0 | AI26: 0 | AJ26: 0 | AK26: 0 | AL26: 0 | AM26: 0 | AN26: 0 | AO26: 0 | AP26: 0 | AQ26: 0 | AR26: 0 | AS26: 0 | AT26: 0 | AU26: 0 | AV26: 0 | AW26: 0 | AX26: 0 | AY26: 0 | AZ26: 0 | BA26: 0
D27: =SUM(D18:D26) -> #REF!
A28: Fator de desconto | D28: =D14-D27 -> #REF! | O28: =1/((1+$D17)^O29) -> #REF! | P28: =1/((1+$D17)^P29) -> #REF! | Q28: =1/((1+$D17)^Q29) -> #REF! | R28: =1/((1+$D17)^R29) -> #REF! | S28: =1/((1+$D17)^S29) -> #REF! | T28: =1/((1+$D17)^T29) -> #REF! | U28: =1/((1+$D17)^U29) -> #REF! | V28: =1/((1+$D17)^V29) -> #REF! | ... BA28: =1/((1+$D17)^BA29) -> #REF!
O29: =#REF! -> #REF! | P29: =#REF! -> #REF! | Q29: =#REF! -> #REF! | R29: =#REF! -> #REF! | S29: =#REF! -> #REF! | T29: =#REF! -> #REF! | U29: =#REF! -> #REF! | V29: =#REF! -> #REF! | ... BA29: =#REF! -> #REF!
A31: CONTRAPRESTAÇÃO | B31: K R$
O32: =O33/O2 -> 6711208.8 | P32: =P33/P2 -> 6567403.3 | Q32: =Q33/Q2 -> 6425279.1 | R32: =R33/R2 -> 6286836.9 | S32: =S33/S2 -> 6151954.4 | T32: =T33/T2 -> 6018678.5 | U32: =U33/U2 -> 5888839 | V32: =V33/V2 -> 5762322.9 | ... AW32: =AW33/AW2 -> 3183751.1
A33: Contraprestação | D33: =1/1000 -> 0.001 | E33: K R$/MM R$ | M33: 30 | O33: ='Receita CP'!O7 -> 7190413.3 | P33: ='Receita CP'!P7 -> 7247429.9 | Q33: ='Receita CP'!Q7 -> 7303306.9 | R33: ='Receita CP'!R7 -> 7360324.7 | S33: ='Receita CP'!S7 -> 7418483.2 | T33: ='Receita CP'!T7 -> 7475502.2 | U33: ='Receita CP'!U7 -> 7533662.1 | V33: ='Receita CP'!V7 -> 7592962.7 | ... AW33: ='Receita CP'!AW7 -> 9318754
A35: RCL | K35: =SUM(K36:K36) -> 617.28054 | L35: =SUM(L36:L36) -> 712.44526 | M35: =SUM(M36:M36) -> 797.27606 | N35: =SUM(N36:N36) -> 859.92069 | O35: =SUM(O36:O36) -> 899.2207 | P35: =SUM(P36:P36) -> 943.85064 | Q35: =SUM(Q36:Q36) -> 991.51226 | R35: =SUM(R36:R36) -> 1041.3356 | ... AW35: =SUM(AW36:AW36) -> 4760.5982
B36: MM R$ | C36: finbraRREO | K36: 617.28054 | L36: 712.44526 | M36: 797.27606 | N36: =M36*(1+N$37)*(N$2/M$2) -> 859.92069 | O36: =N36*(1+O$37)*(O$2/N$2) -> 899.2207 | P36: =O36*(1+P$37)*(P$2/O$2) -> 943.85064 | Q36: =P36*(1+Q$37)*(Q$2/P$2) -> 991.51226 | R36: =Q36*(1+R$37)*(R$2/Q$2) -> 1041.3356 | S36: =R36*(1+S$37)*(S$2/R$2) -> 1093.6625 | T36: =S36*(1+T$37)*(T$2/S$2) -> 1148.6188 | U36: =T36*(1+U$37)*(U$2/T$2) -> 1206.3366 | ... AW36: =AV36*(1+AW$37)*(AW$2/AV$2) -> 4760.5982
A37: Txa. PIB real | B37: %a.a. | M37: =MacroEco!X34 -> 0.046194216 | N37: =MacroEco!Y34 -> 0.0278 | O37: =MacroEco!Z34 -> 0.01034 | P37: =MacroEco!AA34 -> 0.01906 | Q37: =MacroEco!AB34 -> 0.0199 | R37: =MacroEco!AC34 -> 0.01966 | S37: =MacroEco!AD34 -> 0.01966 | T37: =MacroEco!AE34 -> 0.01966 | ... BA37: =MacroEco!BL34 -> 0.01966
A39: %RCL | D39: =MAX(D40:D40) -> 7996.272 | F39: OBS> | G39: comprometimento da RCL reduz ao longo do tempo pq a diluição ocorre com o crescimento do PIB per capita | O39: =O33/O35 -> 7996.272 | P39: =P33/P35 -> 7678.5771 | Q39: =Q33/Q35 -> 7365.8261 | R39: =R33/R35 -> 7068.1584 | S39: =S33/S35 -> 6783.1561 | T39: =T33/T35 -> 6508.2535 | U39: =U33/U35 -> 6245.0744 | V39: =V33/V35 -> 5993.0809 | ... AW39: =AW33/AW35 -> 1957.4754
B40: % | D40: =MAX(O40:AW40) -> 7996.272 | E40: =IF(D40<5%,"ok","ERRO") -> ERRO | O40: =O33/O36 -> 7996.272 | P40: =P33/P36 -> 7678.5771 | Q40: =Q33/Q36 -> 7365.8261 | R40: =R33/R36 -> 7068.1584 | S40: =S33/S36 -> 6783.1561 | T40: =T33/T36 -> 6508.2535 | U40: =U33/U36 -> 6245.0744 | V40: =V33/V36 -> 5993.0809 | ... AW40: =AW33/AW36 -> 1957.4754
A42: Cenários com cobrança de taxa
A43: População atendida | B43: hab
A44: Habitantes por domicílio | D44: 2.4 | E44: hab/domicílio | O44: =OPERACIONAL!#REF! -> #REF! | P44: =OPERACIONAL!#REF! -> #REF! | Q44: =OPERACIONAL!#REF! -> #REF! | R44: =OPERACIONAL!K4 -> 254313 | S44: =OPERACIONAL!L4 -> 256230 | T44: =OPERACIONAL!M4 -> 258242 | U44: =OPERACIONAL!N4 -> 260277 | V44: =OPERACIONAL!O4 -> 262335 | W44: =OPERACIONAL!P4 -> 264416 | X44: =OPERACIONAL!Q4 -> 266189 | Y44: =OPERACIONAL!R4 -> 268315 | ... AW44: =OPERACIONAL!AP4 -> 321923
A45: Número de domicílios | O45: =O44/$D$44 -> #REF! | P45: =P44/$D$44 -> #REF! | Q45: =Q44/$D$44 -> #REF! | R45: =R44/$D$44 -> 105963.75 | S45: =S44/$D$44 -> 106762.5 | T45: =T44/$D$44 -> 107600.83 | U45: =U44/$D$44 -> 108448.75 | V45: =V44/$D$44 -> 109306.25 | ... AW45: =AW44/$D$44 -> 134134.58
A47: Cenário 1 | D47: =1/1000000 -> 1e-06 | E47: R$/MM R$
...

Sheet LOTE 1
A1: Controle
BM3: Com inflação | BP3: Alternativa 1
A4: Modelo Real ou nominal | B4: Com inflação | D4: WACC | E4: 0.1 | BM4: Sem inflação
A5: VPL | B5: ='DRE_URE MARÍLIA-BIO'!I80 -> 93296696 | C5: MM R$ | D5: TIR projeto | E5: ='DRE_URE MARÍLIA-BIO+GAS'!I79 -> 0.11637598
D6: Payback | E6: ='DRE_URE MARÍLIA-BIO+GAS'!I81 -> 6.7 | G6: COM LPU | H6: SEM LPU
A7: Contraprestação fixa | B7: 2.8540916 | C7: MM R$/ano | G7: 2.8540916 | H7: 2.8540916
A8: Saldo final ativo financeiro | B8: =#REF! -> #REF! | G8: =#REF! -> #REF! | H8: =#REF! -> #REF!
A9: Contraprestação variável - Parcela B Volume | B9: 110 | C9: R$/ton | G9: 110 | H9: 110
A10: Contraprestação variável - Parcela C População | B10: 4.7269692 | C10: R$/hab/mês | G10: 4.7269692 | H10: 2.9928665
A12: Sensibilidade preço de recicláveis | B12: 0 | G12: 0 | H12: 0
A13: Sensibilidade crédito recicláveis | B13: 0 | G13: 0 | H13: 0
A14: Outorga variável | B14: 0 | G14: 0 | H14: 0
A15: Anos de carência de outorga variável | B15: 0 | G15: 0 | H15: 0
A16: Primeiro ano de pagamento integral | B16: 1 | G16: 1 | H16: 1
A18: Fator Capex | B18: 1 | G18: 1 | H18: 1
A19: Fator Opex | B19: 1 | G19: 1 | H19: 1
A21: Capital social mínimo 1o ano | B21: 10 | C21: MM R$ | G21: 10 | H21: 10
A23: Considera limpeza urbana? | B23: 1 | C23: [1=sim;0=não] | G23: 1 | H23: 0
A25: Alavancagem alvo | B25: 1 | G25: 1 | H25: 1
A27: Síntese
A28: Componentes de valor / Waterfall VPL
I29: =YEAR(Premissas!$D$13) -> 2025 | J29: =I29+1 -> 2026 | K29: =J29+1 -> 2027 | L29: =K29+1 -> 2028 | M29: =L29+1 -> 2029 | N29: =M29+1 -> 2030 | O29: =N29+1 -> 2031 | P29: =O29+1 -> 2032 | Q29: =P29+1 -> 2033 | ... AQ29: =AP29+1 -> 2059
A30: Índice de inflação brasileira (IPCA) | I30: =MacroEco!AA$8 -> 1.0714036 | J30: =MacroEco!AB$8 -> 1.1035457 | K30: =MacroEco!AC$8 -> 1.1366521 | L30: =MacroEco!AD$8 -> 1.1707517 | M30: =MacroEco!AE$8 -> 1.2058742 | N30: =MacroEco!AF$8 -> 1.2420504 | O30: =MacroEco!AG$8 -> 1.2793119 | P30: =MacroEco!AH$8 -> 1.3176913 | ... AQ30: =MacroEco!BI$8 -> 2.9269732
A32: Em termos nominais
A33: Receita Bruta - URE MARÍLIA - BIO | D33: =SUM(I33:AR33) -> 6.4772826e+08 | I33: =SUM(I34:I38) -> 480090.43 | J33: =SUM(J34:J38) -> 19031970 | K33: =SUM(K34:K38) -> 19032156 | L33: =SUM(L34:L38) -> 19032349 | M33: =SUM(M34:M38) -> 19032550 | N33: =SUM(N34:N38) -> 19032757 | O33: =SUM(O34:O38) -> 19032973 | P33: =SUM(P34:P38) -> 19033197 | ... AQ33: =SUM(AQ34:AQ38) -> 19043151
A34: (+) Receita Contraprestação fixa | D34: =SUM(I34:AR34) -> 229132800 | I34: ='DRE_URE MARÍLIA-BIO+GAS'!E8 -> 0 | J34: ='DRE_URE MARÍLIA-BIO+GAS'!F8 -> 6739200 | K34: ='DRE_URE MARÍLIA-BIO+GAS'!G8 -> 6739200 | L34: ='DRE_URE MARÍLIA-BIO+GAS'!H8 -> 6739200 | M34: ='DRE_URE MARÍLIA-BIO+GAS'!I8 -> 6739200 | N34: ='DRE_URE MARÍLIA-BIO+GAS'!J8 -> 6739200 | O34: ='DRE_URE MARÍLIA-BIO+GAS'!K8 -> 6739200 | P34: ='DRE_URE MARÍLIA-BIO+GAS'!L8 -> 6739200 | ... AP34: ='DRE_URE MARÍLIA-BIO+GAS'!AL8 -> 6739200 | AQ34: =AP34 -> 6739200
A35: (+) Receita Reciclável | D35: =SUM(I35:AR35) -> 332157 | I35: ='Receita Acessórias'!O18 -> 4710.4288 | J35: ='Receita Acessórias'!P18 -> 4890.2048 | K35: ='Receita Acessórias'!Q18 -> 5075.7357 | L35: ='Receita Acessórias'!R18 -> 5268.8133 | M35: ='Receita Acessórias'!S18 -> 5469.748 | N35: ='Receita Acessórias'!T18 -> 5677.1311 | O35: ='Receita Acessórias'!U18 -> 5892.9261 | P35: ='Receita Acessórias'!V18 -> 6117.478 | ... AP35: ='Receita Acessórias'!AV18 -> 16071.17 | AQ35: =AP35 -> 16071.17
A36: (+) Receita Biometano | D36: =SUM(I36:AR36) -> 257040000 | I36: ='DRE_URE MARÍLIA-BIO+GAS'!E5 -> 0 | J36: ='DRE_URE MARÍLIA-BIO+GAS'!G5 -> 7560000 | K36: ='DRE_URE MARÍLIA-BIO+GAS'!H5 -> 7560000 | L36: ='DRE_URE MARÍLIA-BIO+GAS'!I5 -> 7560000 | M36: ='DRE_URE MARÍLIA-BIO+GAS'!J5 -> 7560000 | N36: ='DRE_URE MARÍLIA-BIO+GAS'!K5 -> 7560000 | O36: ='DRE_URE MARÍLIA-BIO+GAS'!L5 -> 7560000 | P36: ='DRE_URE MARÍLIA-BIO+GAS'!M5 -> 7560000 | Q36: ='DRE_URE MARÍLIA-BIO+GAS'!N5 -> 7560000 | ... AP36: ='DRE_URE MARÍLIA-BIO+GAS'!AM5 -> 7560000 | AQ36: =AP36 -> 7560000
A37: (+) Receita CO2 | D37: =SUM(I37:AR37) -> 144585000 | I37: ='DRE_URE MARÍLIA-BIO+GAS'!E7 -> 0 | J37: ='DRE_URE MARÍLIA-BIO+GAS'!G7 -> 4252500 | K37: ='DRE_URE MARÍLIA-BIO+GAS'!H7 -> 4252500 | L37: ='DRE_URE MARÍLIA-BIO+GAS'!I7 -> 4252500 | M37: ='DRE_URE MARÍLIA-BIO+GAS'!J7 -> 4252500 | N37: ='DRE_URE MARÍLIA-BIO+GAS'!K7 -> 4252500 | O37: ='DRE_URE MARÍLIA-BIO+GAS'!L7 -> 4252500 | P37: ='DRE_URE MARÍLIA-BIO+GAS'!M7 -> 4252500 | Q37: ='DRE_URE MARÍLIA-BIO+GAS'!N7 -> 4252500 | ... AP37: ='DRE_URE MARÍLIA-BIO+GAS'!AM7 -> 4252500 | AQ37: =AP37 -> 4252500
A38: (+) CBIOS | D38: =SUM(I38:AR38) -> 16638300 | I38: ='DRE_URE MARÍLIA-BIO+GAS'!F10 -> 475380 | J38: ='DRE_URE MARÍLIA-BIO+GAS'!G10 -> 475380 | K38: ='DRE_URE MARÍLIA-BIO+GAS'!H10 -> 475380 | L38: ='DRE_URE MARÍLIA-BIO+GAS'!I10 -> 475380 | M38: ='DRE_URE MARÍLIA-BIO+GAS'!J10 -> 475380 | N38: ='DRE_URE MARÍLIA-BIO+GAS'!K10 -> 475380 | O38: ='DRE_URE MARÍLIA-BIO+GAS'!L10 -> 475380 | P38: ='DRE_URE MARÍLIA-BIO+GAS'!M10 -> 475380 | ... AP38: ='DRE_URE MARÍLIA-BIO+GAS'!AM10 -> 475380 | AQ38: =AP38 -> 475380
A39: Impostos | D39: =SUM(I39:AR39) -> -1.8693681e+08 | I39: =SUM(I40:I41) -> 0 | J39: =SUM(J40:J41) -> -4517822.2 | K39: =SUM(K40:K41) -> -5527848.2 | L39: =SUM(L40:L41) -> -5527848.2 | M39: =SUM(M40:M41) -> -5527848.2 | N39: =SUM(N40:N41) -> -5527848.2 | O39: =SUM(O40:O41) -> -5527848.2 | P39: =SUM(P40:P41) -> -5527848.2 | ... AQ39: =SUM(AQ40:AQ41) -> -5527848.2
A40: (-) Impostos Serviço | D40: =SUM(I40:AR40) -> -77905152 | I40: ='DRE_URE MARÍLIA-BIO+GAS'!E41 -> 0 | J40: ='DRE_URE MARÍLIA-BIO+GAS'!F41 -> -2291328 | K40: ='DRE_URE MARÍLIA-BIO+GAS'!G41 -> -2291328 | L40: ='DRE_URE MARÍLIA-BIO+GAS'!H41 -> -2291328 | M40: ='DRE_URE MARÍLIA-BIO+GAS'!I41 -> -2291328 | N40: ='DRE_URE MARÍLIA-BIO+GAS'!J41 -> -2291328 | O40: ='DRE_URE MARÍLIA-BIO+GAS'!K41 -> -2291328 | P40: ='DRE_URE MARÍLIA-BIO+GAS'!L41 -> -2291328 | ... AQ40: ='DRE_URE MARÍLIA-BIO+GAS'!AM41 -> -2291328
A41: (-) Impostos Produto | D41: =SUM(I41:AR41) -> -1.0903166e+08 | I41: ='DRE_URE MARÍLIA-BIO+GAS'!E12 -> 0 | J41: ='DRE_URE MARÍLIA-BIO+GAS'!F12 -> -2226494.2 | K41: ='DRE_URE MARÍLIA-BIO+GAS'!G12 -> -3236520.2 | L41: ='DRE_URE MARÍLIA-BIO+GAS'!H12 -> -3236520.2 | M41: ='DRE_URE MARÍLIA-BIO+GAS'!I12 -> -3236520.2 | N41: ='DRE_URE MARÍLIA-BIO+GAS'!J12 -> -3236520.2 | O41: ='DRE_URE MARÍLIA-BIO+GAS'!K12 -> -3236520.2 | P41: ='DRE_URE MARÍLIA-BIO+GAS'!L12 -> -3236520.2 | ... AQ41: ='DRE_URE MARÍLIA-BIO+GAS'!AM12 -> -3236520.2
A42: OPEX | D42: =SUM(I42:AR42) -> -1.7836593e+08 | I42: =SUM(I43:I43) -> -954720 | J42: =SUM(J43:J43) -> -5059006.2 | K42: =SUM(K43:K43) -> -5222794.2 | L42: =SUM(L43:L43) -> -5222794.2 | M42: =SUM(M43:M43) -> -5222794.2 | N42: =SUM(N43:N43) -> -5222794.2 | O42: =SUM(O43:O43) -> -5222794.2 | P42: =SUM(P43:P43) -> -5222794.2 | ... AQ42: =SUM(AQ43:AQ43) -> -5222794.2
A43: (-) Custos com operacionais | D43: =SUM(J43:AR43) -> -1.7741121e+08 | I43: =Opex!Z57*-1 -> -954720 | J43: =Opex!AA57*-1 -> -5059006.2 | K43: =Opex!AB57*-1 -> -5222794.2 | L43: =Opex!AC57*-1 -> -5222794.2 | M43: =Opex!AD57*-1 -> -5222794.2 | N43: =Opex!AE57*-1 -> -5222794.2 | O43: =Opex!AF57*-1 -> -5222794.2 | P43: =Opex!AG57*-1 -> -5222794.2 | ... AP43: =Opex!BG57*-1 -> -5222794.2 | AQ43: =AP43 -> -5222794.2
A44: Custos de construção | D44: =SUM(I44:AR44) -> -40600000 | I44: =I45 -> 0 | J44: =J45 -> -4060000 | K44: =K45 -> -4060000 | L44: =L45 -> -4060000 | M44: =M45 -> -4060000 | N44: =N45 -> -4060000 | O44: =O45 -> -4060000 | P44: =P45 -> -4060000 | ... AQ44: =AQ45 -> 0
A45: (-) Depreciação/Amortização | D45: =SUM(I45:AR45) -> -40600000 | I45: ='DRE_URE MARÍLIA-BIO+GAS'!E36 -> 0 | J45: ='DRE_URE MARÍLIA-BIO+GAS'!F36 -> -4060000 | K45: ='DRE_URE MARÍLIA-BIO+GAS'!G36 -> -4060000 | L45: ='DRE_URE MARÍLIA-BIO+GAS'!H36 -> -4060000 | M45: ='DRE_URE MARÍLIA-BIO+GAS'!I36 -> -4060000 | N45: ='DRE_URE MARÍLIA-BIO+GAS'!J36 -> -4060000 | O45: ='DRE_URE MARÍLIA-BIO+GAS'!K36 -> -4060000 | P45: ='DRE_URE MARÍLIA-BIO+GAS'!L36 -> -4060000 | ... AQ45: ='DRE_URE MARÍLIA-BIO+GAS'!AM36 -> 0
A46: (=) EBIT | D46: =SUM(I46:AR46) -> 4.2019144e+08 | I46: =SUM(I47:I49) -> 480090.43 | J46: =SUM(J47:J49) -> 10454148 | K46: =SUM(K47:K49) -> 9444307.5 | L46: =SUM(L47:L49) -> 9444500.6 | M46: =SUM(M47:M49) -> 9444701.5 | N46: =SUM(N47:N49) -> 9444908.9 | O46: =SUM(O47:O49) -> 9445124.7 | P46: =SUM(P47:P49) -> 9445349.2 | ... AQ46: =SUM(AQ47:AQ49) -> 13515303
A47: (-) Impostos sobre EBIT | D47: =SUM(I47:AR47) -> -1.8693681e+08 | I47: =I39 -> 0 | J47: =J39 -> -4517822.2 | K47: =K39 -> -5527848.2 | L47: =L39 -> -5527848.2 | M47: =M39 -> -5527848.2 | N47: =N39 -> -5527848.2 | O47: =O39 -> -5527848.2 | P47: =P39 -> -5527848.2 | ... AQ47: =AQ39 -> -5527848.2
A48: (+) Receita Bruta | D48: =SUM(I48:AR48) -> 6.4772826e+08 | I48: =I33 -> 480090.43 | J48: =J33 -> 19031970 | K48: =K33 -> 19032156 | L48: =L33 -> 19032349 | M48: =M33 -> 19032550 | N48: =N33 -> 19032757 | O48: =O33 -> 19032973 | P48: =P33 -> 19033197 | ... AQ48: =AQ33 -> 19043151
...

Sheet LOTE 2
A1: Controle
BM3: Com inflação | BP3: Alternativa 1
A4: Modelo Real ou nominal | B4: Com inflação | D4: WACC | E4: 0.1 | BM4: Sem inflação
A5: VPL | B5: ='DRE_URE MARÍLIA-GAS'!I80 -> 62373297 | C5: MM R$ | D5: TIR projeto | E5: ='DRE_URE MARÍLIA-BIO+GAS'!I79 -> 0.11637598
D6: Payback | E6: ='DRE_URE MARÍLIA-BIO+GAS'!I81 -> 6.7 | G6: COM LPU | H6: SEM LPU
A7: Contraprestação fixa | B7: 2.8540916 | C7: MM R$/ano | G7: 2.8540916 | H7: 2.8540916
A8: Saldo final ativo financeiro | B8: =#REF! -> #REF! | G8: =#REF! -> #REF! | H8: =#REF! -> #REF!
A9: Contraprestação variável - Parcela B Volume | B9: 110 | C9: R$/ton | G9: 110 | H9: 110
A10: Contraprestação variável - Parcela C População | B10: 4.7269692 | C10: R$/hab/mês | G10: 4.7269692 | H10: 2.9928665
A12: Sensibilidade preço de recicláveis | B12: 0 | G12: 0 | H12: 0
A13: Sensibilidade crédito recicláveis | B13: 0 | G13: 0 | H13: 0
A14: Outorga variável | B14: 0 | G14: 0 | H14: 0
A15: Anos de carência de outorga variável | B15: 0 | G15: 0 | H15: 0
A16: Primeiro ano de pagamento integral | B16: 1 | G16: 1 | H16: 1
A18: Fator Capex | B18: 1 | G18: 1 | H18: 1
A19: Fator Opex | B19: 1 | G19: 1 | H19: 1
A21: Capital social mínimo 1o ano | B21: 10 | C21: MM R$ | G21: 10 | H21: 10
A23: Considera limpeza urbana? | B23: 1 | C23: [1=sim;0=não] | G23: 1 | H23: 0
A25: Alavancagem alvo | B25: 1 | G25: 1 | H25: 1
A27: Síntese
A28: Componentes de valor / Waterfall VPL
I29: =YEAR(Premissas!$D$13) -> 2025 | J29: =I29+1 -> 2026 | K29: =J29+1 -> 2027 | L29: =K29+1 -> 2028 | M29: =L29+1 -> 2029 | N29: =M29+1 -> 2030 | O29: =N29+1 -> 2031 | P29: =O29+1 -> 2032 | Q29: =P29+1 -> 2033 | ... AQ29: =AP29+1 -> 2059
A30: Índice de inflação brasileira (IPCA) | I30: =MacroEco!AA$8 -> 1.0714036 | J30: =MacroEco!AB$8 -> 1.1035457 | K30: =MacroEco!AC$8 -> 1.1366521 | L30: =MacroEco!AD$8 -> 1.1707517 | M30: =MacroEco!AE$8 -> 1.2058742 | N30: =MacroEco!AF$8 -> 1.2420504 | O30: =MacroEco!AG$8 -> 1.2793119 | P30: =MacroEco!AH$8 -> 1.3176913 | ... AQ30: =MacroEco!BI$8 -> 2.9269732
A32: Em termos nominais
A33: Receita Bruta - URE MARÍLIA - GAS | D33: =SUM(I33:AR33) -> 7.6194106e+08 | I33: =SUM(I34:I38) -> 480090.43 | J33: =SUM(J34:J38) -> 22391170 | K33: =SUM(K34:K38) -> 22391356 | L33: =SUM(L34:L38) -> 22391549 | M33: =SUM(M34:M38) -> 22391750 | N33: =SUM(N34:N38) -> 22391957 | O33: =SUM(O34:O38) -> 22392173 | P33: =SUM(P34:P38) -> 22392397 | ... AQ33: =SUM(AQ34:AQ38) -> 22402351
A34: (+) Receita Contraprestação fixa | D34: =SUM(I34:AR34) -> 229132800 | I34: ='DRE_URE MARÍLIA-BIO+GAS'!E8 -> 0 | J34: ='DRE_URE MARÍLIA-BIO+GAS'!F8 -> 6739200 | K34: ='DRE_URE MARÍLIA-BIO+GAS'!G8 -> 6739200 | L34: ='DRE_URE MARÍLIA-BIO+GAS'!H8 -> 6739200 | M34: ='DRE_URE MARÍLIA-BIO+GAS'!I8 -> 6739200 | N34: ='DRE_URE MARÍLIA-BIO+GAS'!J8 -> 6739200 | O34: ='DRE_URE MARÍLIA-BIO+GAS'!K8 -> 6739200 | P34: ='DRE_URE MARÍLIA-BIO+GAS'!L8 -> 6739200 | ... AP34: ='DRE_URE MARÍLIA-BIO+GAS'!AL8 -> 6739200 | AQ34: =AP34 -> 6739200
A35: (+) Receita Reciclável | D35: =SUM(I35:AR35) -> 332157 | I35: ='Receita Acessórias'!O18 -> 4710.4288 | J35: ='Receita Acessórias'!P18 -> 4890.2048 | K35: ='Receita Acessórias'!Q18 -> 5075.7357 | L35: ='Receita Acessórias'!R18 -> 5268.8133 | M35: ='Receita Acessórias'!S18 -> 5469.748 | N35: ='Receita Acessórias'!T18 -> 5677.1311 | O35: ='Receita Acessórias'!U18 -> 5892.9261 | P35: ='Receita Acessórias'!V18 -> 6117.478 | ... AP35: ='Receita Acessórias'!AV18 -> 16071.17 | AQ35: =AP35 -> 16071.17
A36: (+) Receita Energia Elétrica | D36: =SUM(I36:AR36) -> 371252800 | I36: ='DRE_URE MARÍLIA-BIO+GAS'!E6 -> 0 | J36: ='DRE_URE MARÍLIA-BIO+GAS'!G6 -> 10919200 | K36: ='DRE_URE MARÍLIA-BIO+GAS'!H6 -> 10919200 | L36: ='DRE_URE MARÍLIA-BIO+GAS'!I6 -> 10919200 | M36: ='DRE_URE MARÍLIA-BIO+GAS'!J6 -> 10919200 | N36: ='DRE_URE MARÍLIA-BIO+GAS'!K6 -> 10919200 | O36: ='DRE_URE MARÍLIA-BIO+GAS'!L6 -> 10919200 | P36: ='DRE_URE MARÍLIA-BIO+GAS'!M6 -> 10919200 | Q36: ='DRE_URE MARÍLIA-BIO+GAS'!N6 -> 10919200 | ... AP36: ='DRE_URE MARÍLIA-BIO+GAS'!AM6 -> 10919200 | AQ36: =AP36 -> 10919200
A37: (+) Receita CO2 | D37: =SUM(I37:AR37) -> 144585000 | I37: ='DRE_URE MARÍLIA-BIO+GAS'!E7 -> 0 | J37: ='DRE_URE MARÍLIA-BIO+GAS'!G7 -> 4252500 | K37: ='DRE_URE MARÍLIA-BIO+GAS'!H7 -> 4252500 | L37: ='DRE_URE MARÍLIA-BIO+GAS'!I7 -> 4252500 | M37: ='DRE_URE MARÍLIA-BIO+GAS'!J7 -> 4252500 | N37: ='DRE_URE MARÍLIA-BIO+GAS'!K7 -> 4252500 | O37: ='DRE_URE MARÍLIA-BIO+GAS'!L7 -> 4252500 | P37: ='DRE_URE MARÍLIA-BIO+GAS'!M7 -> 4252500 | Q37: ='DRE_URE MARÍLIA-BIO+GAS'!N7 -> 4252500 | ... AP37: ='DRE_URE MARÍLIA-BIO+GAS'!AM7 -> 4252500 | AQ37: =AP37 -> 4252500
A38: (+) CBIOS | D38: =SUM(I38:AR38) -> 16638300 | I38: ='DRE_URE MARÍLIA-BIO+GAS'!F10 -> 475380 | J38: ='DRE_URE MARÍLIA-BIO+GAS'!G10 -> 475380 | K38: ='DRE_URE MARÍLIA-BIO+GAS'!H10 -> 475380 | L38: ='DRE_URE MARÍLIA-BIO+GAS'!I10 -> 475380 | M38: ='DRE_URE MARÍLIA-BIO+GAS'!J10 -> 475380 | N38: ='DRE_URE MARÍLIA-BIO+GAS'!K10 -> 475380 | O38: ='DRE_URE MARÍLIA-BIO+GAS'!L10 -> 475380 | P38: ='DRE_URE MARÍLIA-BIO+GAS'!M10 -> 475380 | ... AP38: ='DRE_URE MARÍLIA-BIO+GAS'!AM10 -> 475380 | AQ38: =AP38 -> 475380
A39: Impostos | D39: =SUM(I39:AR39) -> -1.8693681e+08 | I39: =SUM(I40:I41) -> 0 | J39: =SUM(J40:J41) -> -4517822.2 | K39: =SUM(K40:K41) -> -5527848.2 | L39: =SUM(L40:L41) -> -5527848.2 | M39: =SUM(M40:M41) -> -5527848.2 | N39: =SUM(N40:N41) -> -5527848.2 | O39: =SUM(O40:O41) -> -5527848.2 | P39: =SUM(P40:P41) -> -5527848.2 | ... AQ39: =SUM(AQ40:AQ41) -> -5527848.2
A40: (-) Impostos Serviço | D40: =SUM(I40:AR40) -> -77905152 | I40: ='DRE_URE MARÍLIA-BIO+GAS'!E41 -> 0 | J40: ='DRE_URE MARÍLIA-BIO+GAS'!F41 -> -2291328 | K40: ='DRE_URE MARÍLIA-BIO+GAS'!G41 -> -2291328 | L40: ='DRE_URE MARÍLIA-BIO+GAS'!H41 -> -2291328 | M40: ='DRE_URE MARÍLIA-BIO+GAS'!I41 -> -2291328 | N40: ='DRE_URE MARÍLIA-BIO+GAS'!J41 -> -2291328 | O40: ='DRE_URE MARÍLIA-BIO+GAS'!K41 -> -2291328 | P40: ='DRE_URE MARÍLIA-BIO+GAS'!L41 -> -2291328 | ... AQ40: ='DRE_URE MARÍLIA-BIO+GAS'!AM41 -> -2291328
A41: (-) Impostos Produto | D41: =SUM(I41:AR41) -> -1.0903166e+08 | I41: ='DRE_URE MARÍLIA-BIO+GAS'!E12 -> 0 | J41: ='DRE_URE MARÍLIA-BIO+GAS'!F12 -> -2226494.2 | K41: ='DRE_URE MARÍLIA-BIO+GAS'!G12 -> -3236520.2 | L41: ='DRE_URE MARÍLIA-BIO+GAS'!H12 -> -3236520.2 | M41: ='DRE_URE MARÍLIA-BIO+GAS'!I12 -> -3236520.2 | N41: ='DRE_URE MARÍLIA-BIO+GAS'!J12 -> -3236520.2 | O41: ='DRE_URE MARÍLIA-BIO+GAS'!K12 -> -3236520.2 | P41: ='DRE_URE MARÍLIA-BIO+GAS'!L12 -> -3236520.2 | ... AQ41: ='DRE_URE MARÍLIA-BIO+GAS'!AM12 -> -3236520.2
A42: OPEX | D42: =SUM(I42:AR42) -> -1.7836593e+08 | I42: =SUM(I43:I43) -> -954720 | J42: =SUM(J43:J43) -> -5059006.2 | K42: =SUM(K43:K43) -> -5222794.2 | L42: =SUM(L43:L43) -> -5222794.2 | M42: =SUM(M43:M43) -> -5222794.2 | N42: =SUM(N43:N43) -> -5222794.2 | O42: =SUM(O43:O43) -> -5222794.2 | P42: =SUM(P43:P43) -> -5222794.2 | ... AQ42: =SUM(AQ43:AQ43) -> -5222794.2
A43: (-) Custos com operacionais | D43: =SUM(J43:AR43) -> -1.7741121e+08 | I43: =Opex!Z57*-1 -> -954720 | J43: =Opex!AA57*-1 -> -5059006.2 | K43: =Opex!AB57*-1 -> -5222794.2 | L43: =Opex!AC57*-1 -> -5222794.2 | M43: =Opex!AD57*-1 -> -5222794.2 | N43: =Opex!AE57*-1 -> -5222794.2 | O43: =Opex!AF57*-1 -> -5222794.2 | P43: =Opex!AG57*-1 -> -5222794.2 | ... AP43: =Opex!BG57*-1 -> -5222794.2 | AQ43: =AP43 -> -5222794.2
A44: Custos de construção | D44: =SUM(I44:AR44) -> -40600000 | I44: =I45 -> 0 | J44: =J45 -> -4060000 | K44: =K45 -> -4060000 | L44: =L45 -> -4060000 | M44: =M45 -> -4060000 | N44: =N45 -> -4060000 | O44: =O45 -> -4060000 | P44: =P45 -> -4060000 | ... AQ44: =AQ45 -> 0
A45: (-) Depreciação/Amortização | D45: =SUM(I45:AR45) -> -40600000 | I45: ='DRE_URE MARÍLIA-BIO+GAS'!E36 -> 0 | J45: ='DRE_URE MARÍLIA-BIO+GAS'!F36 -> -4060000 | K45: ='DRE_URE MARÍLIA-BIO+GAS'!G36 -> -4060000 | L45: ='DRE_URE MARÍLIA-BIO+GAS'!H36 -> -4060000 | M45: ='DRE_URE MARÍLIA-BIO+GAS'!I36 -> -4060000 | N45: ='DRE_URE MARÍLIA-BIO+GAS'!J36 -> -4060000 | O45: ='DRE_URE MARÍLIA-BIO+GAS'!K36 -> -4060000 | P45: ='DRE_URE MARÍLIA-BIO+GAS'!L36 -> -4060000 | ... AQ45: ='DRE_URE MARÍLIA-BIO+GAS'!AM36 -> 0
A46: (=) EBIT | D46: =SUM(I46:AR46) -> 5.3440424e+08 | I46: =SUM(I47:I49) -> 480090.43 | J46: =SUM(J47:J49) -> 13813348 | K46: =SUM(K47:K49) -> 12803507 | L46: =SUM(L47:L49) -> 12803701 | M46: =SUM(M47:M49) -> 12803901 | N46: =SUM(N47:N49) -> 12804109 | O46: =SUM(O47:O49) -> 12804325 | P46: =SUM(P47:P49) -> 12804549 | ... AQ46: =SUM(AQ47:AQ49) -> 16874503
A47: (-) Impostos sobre EBIT | D47: =SUM(I47:AR47) -> -1.8693681e+08 | I47: =I39 -> 0 | J47: =J39 -> -4517822.2 | K47: =K39 -> -5527848.2 | L47: =L39 -> -5527848.2 | M47: =M39 -> -5527848.2 | N47: =N39 -> -5527848.2 | O47: =O39 -> -5527848.2 | P47: =P39 -> -5527848.2 | ... AQ47: =AQ39 -> -5527848.2
A48: (+) Receita Bruta | D48: =SUM(I48:AR48) -> 7.6194106e+08 | I48: =I33 -> 480090.43 | J48: =J33 -> 22391170 | K48: =K33 -> 22391356 | L48: =L33 -> 22391549 | M48: =M33 -> 22391750 | N48: =N33 -> 22391957 | O48: =O33 -> 22392173 | P48: =P33 -> 22392397 | ... AQ48: =AQ33 -> 22402351
...

Sheet OPERACIONAL
B1: Unid | C1: Fonte | E1: Fator 1 | F1: Unid fator 1 | H1: 2025 | I1: =H1+1 -> 2026 | J1: =I1+1 -> 2027 | K1: =J1+1 -> 2028 | L1: =K1+1 -> 2029 | M1: =L1+1 -> 2030 | N1: =M1+1 -> 2031 | O1: =N1+1 -> 2032 | P1: =O1+1 -> 2033 | ... AP1: =AO1+1 -> 2059
H2: 1 | I2: 2 | J2: 3 | K2: 4 | L2: 5 | M2: 6 | N2: 7 | O2: 8 | P2: 9 | Q2: 10 | R2: 11 | S2: 12 | T2: 13 | U2: 14
A3: POPULAÇÃO E DEMANDA
A4: População atendida | B4: hab | E4: =AVERAGE(H4:AP4) -> 283215.76 | F4: hab | H4: 236158.93 | I4: 241443.17 | J4: 246845.64 | K4: =Apoio!$R10 -> 254313 | L4: =Apoio!$R11 -> 256230 | M4: =Apoio!$R12 -> 258242 | N4: =Apoio!$R13 -> 260277 | O4: =Apoio!$R14 -> 262335 | P4: =Apoio!$R15 -> 264416 | Q4: =Apoio!$R16 -> 266189 | R4: =Apoio!$R17 -> 268315 | S4: =Apoio!$R18 -> 270463 | T4: =Apoio!$R19 -> 272633 | U4: =Apoio!$R20 -> 274826 | V4: =Apoio!$R21 -> 276540 | W4: =Apoio!$R22 -> 278670 | X4: =Apoio!$R23 -> 280823 | Y4: =Apoio!$R24 -> 283000 | Z4: =Apoio!$R25 -> 285200 | AA4: =Apoio!$R26 -> 287296 | AB4: =Apoio!$R28 -> 291807 | AC4: =Apoio!$R29 -> 294098 | AD4: =Apoio!$R29 -> 294098 | AE4: =Apoio!$R30 -> 296413 | AF4: =Apoio!$R31 -> 298476 | AG4: =Apoio!$R32 -> 300781 | AH4: =Apoio!$R33 -> 303110 | AI4: =Apoio!$R34 -> 305463 | AJ4: =Apoio!$R35 -> 307841 | AK4: =Apoio!$R36 -> 310095 | AL4: =Apoio!$R37 -> 312455 | AM4: =Apoio!$R38 -> 314840 | AN4: =Apoio!$R39 -> 317250 | AO4: =Apoio!$R40 -> 319686 | AP4: =Apoio!$R41 -> 321923
A6: DEMANDA DE RESÍDUOS | H6: =SUM(H7) -> 63070 | I6: =SUM(I7) -> 63570 | J6: =SUM(J7) -> 64060 | K6: =SUM(K7) -> 64560 | L6: =SUM(L7) -> 65070 | M6: =SUM(M7) -> 65570 | N6: =SUM(N7) -> 66080 | O6: =SUM(O7) -> 66600 | ... AP6: =SUM(AP7) -> 81730
A7: Geração RSD | B7: t/ano | H7: =Apoio!$T7 -> 63070 | I7: =Apoio!$T8 -> 63570 | J7: =Apoio!$T9 -> 64060 | K7: =Apoio!$T10 -> 64560 | L7: =Apoio!$T11 -> 65070 | M7: =Apoio!$T12 -> 65570 | N7: =Apoio!$T13 -> 66080 | O7: =Apoio!$T14 -> 66600 | P7: =Apoio!$T15 -> 67120 | Q7: =Apoio!$T16 -> 67590 | R7: =Apoio!$T17 -> 68140 | S7: =Apoio!$T18 -> 68690 | T7: =Apoio!$T19 -> 69250 | U7: =Apoio!$T20 -> 69800 | V7: =Apoio!$T21 -> 70210 | W7: =Apoio!$T22 -> 70790 | X7: =Apoio!$T23 -> 71330 | Y7: =Apoio!$T24 -> 71890 | Z7: =Apoio!$T25 -> 72450 | AA7: =Apoio!$T26 -> 72930 | AB7: =Apoio!$T27 -> 73510 | AC7: =Apoio!$T28 -> 74040 | AD7: =Apoio!$T29 -> 74650 | AE7: =Apoio!$T30 -> 75220 | AF7: =Apoio!$T31 -> 75780 | AG7: =Apoio!$T32 -> 76350 | AH7: =Apoio!$T33 -> 76920 | AI7: =Apoio!$T34 -> 77530 | AJ7: =Apoio!$T35 -> 78120 | AK7: =Apoio!$T36 -> 78700 | AL7: =Apoio!$T37 -> 79320 | AM7: =Apoio!$T38 -> 79910 | AN7: =Apoio!$T39 -> 80500 | AO7: =Apoio!$T40 -> 81130 | AP7: =Apoio!$T41 -> 81730
A8: Rejeito | B8: t/ano | E8: 0.16 | H8: =H7*$E$8 -> 10091.2 | I8: =I7*$E$8 -> 10171.2 | J8: =J7*$E$8 -> 10249.6 | K8: =K7*$E$8 -> 10329.6 | L8: =L7*$E$8 -> 10411.2 | M8: =M7*$E$8 -> 10491.2 | N8: =N7*$E$8 -> 10572.8 | O8: =O7*$E$8 -> 10656 | ... AP8: =AP7*$E$8 -> 13076.8
A10: VALORIZAÇÃO DE RESÍDUOS
A11: Fração Úmida | B11: t/ano | E11: 0.45 | H11: =H7*$E$11 -> 28381.5 | I11: =I7*$E$11 -> 28606.5 | J11: =J7*$E$11 -> 28827 | K11: =K7*$E$11 -> 29052 | L11: =L7*$E$11 -> 29281.5 | M11: =M7*$E$11 -> 29506.5 | N11: =N7*$E$11 -> 29736 | O11: =O7*$E$11 -> 29970 | ... AP11: =AP7*$E$11 -> 36778.5
A12: Fração Seca | B12: t/ano | E12: 0.34 | H12: =H7*$E$12 -> 21443.8 | I12: =I7*$E$12 -> 21613.8 | J12: =J7*$E$12 -> 21780.4 | K12: =K7*$E$12 -> 21950.4 | L12: =L7*$E$12 -> 22123.8 | M12: =M7*$E$12 -> 22293.8 | N12: =N7*$E$12 -> 22467.2 | O12: =O7*$E$12 -> 22644 | ... AP12: =AP7*$E$12 -> 27788.2
A13: Metais e Vidros | B13: t/ano | E13: 0.05 | H13: =H7*$E$13 -> 3153.5 | I13: =I7*$E$13 -> 3178.5 | J13: =J7*$E$13 -> 3203 | K13: =K7*$E$13 -> 3228 | L13: =L7*$E$13 -> 3253.5 | M13: =M7*$E$13 -> 3278.5 | N13: =N7*$E$13 -> 3304 | O13: =O7*$E$13 -> 3330 | ... AP13: =AP7*$E$13 -> 4086.5
A15: REJEITOS NÃO VALORIZADOS | H15: =SUM(H17) -> 10091.2 | I15: =SUM(I17) -> 38777.7 | J15: =SUM(J17) -> 39076.6 | K15: =SUM(K17) -> 39381.6 | L15: =SUM(L17) -> 39692.7 | M15: =SUM(M17) -> 39997.7 | N15: =SUM(N17) -> 40308.8 | O15: =SUM(O17) -> 40626 | ... AP15: =SUM(AP17) -> 49855.3
A16: Aterro Sanitário
A17: Massa aterrada total | B17: t/ano | H17: =H8 -> 10091.2 | I17: =SUM(I11,I8) -> 38777.7 | J17: =SUM(J11,J8) -> 39076.6 | K17: =SUM(K11,K8) -> 39381.6 | L17: =SUM(L11,L8) -> 39692.7 | M17: =SUM(M11,M8) -> 39997.7 | N17: =SUM(N11,N8) -> 40308.8 | O17: =SUM(O11,O8) -> 40626 | P17: =SUM(P11,P8) -> 40943.2 | ... AP17: =SUM(AP11,AP8) -> 49855.3

Sheet Receita Acessórias
A1: Receitas Acessórias | B1: MMR$ | O1: 2024 | P1: =O1+1 -> 2025 | Q1: =P1+1 -> 2026 | R1: =Q1+1 -> 2027 | S1: =R1+1 -> 2028 | T1: =S1+1 -> 2029 | U1: =T1+1 -> 2030 | V1: =U1+1 -> 2031 | W1: =V1+1 -> 2032 | ... AV1: =AU1+1 -> 2057
A2: Premissas
A3: Geral
